Workbook

Sheet README
A1: Personal Budget
A3: Monthly | B3: Your layout, unchanged — except the month columns now fill themselves from Transactions.
B4: Edit column D (yellow) to set each segment's monthly budget. Nothing else needs typing.
A5: Budget vs Actual | B5: Budget against this month's spending, per segment, with OVER / Close / OK.
A6: Transactions | B6: The log. The phone app appends here. You never type in it.
A7: Categories | B7: What the app shows as buttons, mirrored from Monthly.
A9: Yellow cells | B9: The only ones you edit: the year, the month on Budget vs Actual, and the budgets.
A10: Do not | B10: Rename tabs, reorder columns, or insert rows above a header — the app matches on name.
A12: Where the numbers | B12: Every month figure is a SUMIFS over Transactions matching Category, Segment,
A13: come from | B13: Month and Year. Log something on the phone and this recalculates on its own.

Sheet Transactions
A1: Row Key | B1: Date | C1: Time | D1: Who | E1: Amount | F1: Currency | G1: Category | H1: Segment | I1: Note | J1: Month | K1: Year | L1: Logged At
A2: 2026-08-27-Wassim-1756315500000-k3f9 | B2: 2026-08-27 | C2: 22:05 | D2: Wassim | E2: 245.5 | F2: AED | G2: Home Expenses | H2: Food Delivery | I2: Talabat | J2: Aug | K2: 2026 | L2: 2026-08-27T18:05:00Z
A3: ↑ one example row. Delete it once real entries arrive. The app appends below.

Sheet Monthly
A1: Year | B1: 2026 | D1: ← every month column below reads this year from Transactions
A2: Index | B2: Category | C2: Summary | D2: Monthly expected | E2: Jan | F2: Feb | G2: Mar | H2: Apr | I2: May | J2: Jun | K2: Jul | L2: Aug | M2: Sep | N2: Oct | O2: Nov | P2: Dec | Q2: Actual YTD | R2: Expected / year
A3: 1 | B3: Jamela & Wassim | C3: Total Home Expenses | D3: =D25 -> 7747.76 | E3: =E25 -> 0 | F3: =F25 -> 0 | G3: =G25 -> 0 | H3: =H25 -> 0 | I3: =I25 -> 0 | J3: =J25 -> 0 | K3: =K25 -> 0 | ... R3: =R25 -> 92973.12
A4: 2 | B4: Jamela & Wassim | C4: Total Transportation | D4: =D38 -> 2310 | E4: =E38 -> 0 | F4: =F38 -> 0 | G4: =G38 -> 0 | H4: =H38 -> 0 | I4: =I38 -> 0 | J4: =J38 -> 0 | K4: =K38 -> 0 | ... R4: =R38 -> 27720
A5: 3 | B5: Jamela & Wassim | C5: Total Personal | D5: =D48 -> 3550 | E5: =E48 -> 0 | F5: =F48 -> 0 | G5: =G48 -> 0 | H5: =H48 -> 0 | I5: =I48 -> 0 | J5: =J48 -> 0 | K5: =K48 -> 0 | ... R5: =R48 -> 42600
A6: 4 | B6: Jamela & Wassim | C6: Total Travel | D6: =D57 -> 1160 | E6: =E57 -> 0 | F6: =F57 -> 0 | G6: =G57 -> 0 | H6: =H57 -> 0 | I6: =I57 -> 0 | J6: =J57 -> 0 | K6: =K57 -> 0 | ... R6: =R57 -> 13920
A7: 5 | B7: Jamela & Wassim | C7: Total Investment | D7: =D65 -> 4200 | E7: =E65 -> 0 | F7: =F65 -> 0 | G7: =G65 -> 0 | H7: =H65 -> 0 | I7: =I65 -> 0 | J7: =J65 -> 0 | K7: =K65 -> 0 | ... R7: =R65 -> 50400
C8: Total Expenses | D8: =SUM(D3:D7) -> 18967.76 | E8: =SUM(E3:E7) -> 0 | F8: =SUM(F3:F7) -> 0 | G8: =SUM(G3:G7) -> 0 | H8: =SUM(H3:H7) -> 0 | I8: =SUM(I3:I7) -> 0 | J8: =SUM(J3:J7) -> 0 | K8: =SUM(K3:K7) -> 0 | ... R8: =SUM(R3:R7) -> 227613.12
A11: Index | B11: Category | C11: Home Expenses | D11: Monthly expected | E11: Jan | F11: Feb | G11: Mar | H11: Apr | I11: May | J11: Jun | K11: Jul | L11: Aug | M11: Sep | N11: Oct | O11: Nov | P11: Dec | Q11: Actual YTD | R11: Expected / year
A12: 1 | B12: Home Expenses | C12: Mortgage/Rent | D12: 3465 | E12: =SUMIFS(Transactions!$E:$E,Transactions!$G:$G,$B12,Transactions!$H:$H,$C12,Transactions!$J:$J,E$11,Transactions!$K:$K,$B$1) -> 0 | F12: =SUMIFS(Transactions!$E:$E,Transactions!$G:$G,$B12,Transactions!$H:$H,$C12,Transactions!$J:$J,F$11,Transactions!$K:$K,$B$1) -> 0 | G12: =SUMIFS(Transactions!$E:$E,Transactions!$G:$G,$B12,Transactions!$H:$H,$C12,Transactions!$J:$J,G$11,Transactions!$K:$K,$B$1) -> 0 | H12: =SUMIFS(Transactions!$E:$E,Transactions!$G:$G,$B12,Transactions!$H:$H,$C12,Transactions!$J:$J,H$11,Transactions!$K:$K,$B$1) -> 0 | I12: =SUMIFS(Transactions!$E:$E,Transactions!$G:$G,$B12,Transactions!$H:$H,$C12,Transactions!$J:$J,I$11,Transactions!$K:$K,$B$1) -> 0 | J12: =SUMIFS(Transactions!$E:$E,Transactions!$G:$G,$B12,Transactions!$H:$H,$C12,Transactions!$J:$J,J$11,Transactions!$K:$K,$B$1) -> 0 | K12: =SUMIFS(Transactions!$E:$E,Transactions!$G:$G,$B12,Transactions!$H:$H,$C12,Transactions!$J:$J,K$11,Transactions!$K:$K,$B$1) -> 0 | L12: =SUMIFS(Transactions!$E:$E,Transactions!$G:$G,$B12,Transactions!$H:$H,$C12,Transactions!$J:$J,L$11,Transactions!$K:$K,$B$1) -> 0 | ... P12: =SUMIFS(Transactions!$E:$E,Transactions!$G:$G,$B12,Transactions!$H:$H,$C12,Transactions!$J:$J,P$11,Transactions!$K:$K,$B$1) -> 0 | Q12: =SUM(E12:P12) -> 0 | R12: =D12*12 -> 41580
A13: 2 | B13: Home Expenses | C13: Phone Bills | D13: 210 | E13: =SUMIFS(Transactions!$E:$E,Transactions!$G:$G,$B13,Transactions!$H:$H,$C13,Transactions!$J:$J,E$11,Transactions!$K:$K,$B$1) -> 0 | F13: =SUMIFS(Transactions!$E:$E,Transactions!$G:$G,$B13,Transactions!$H:$H,$C13,Transactions!$J:$J,F$11,Transactions!$K:$K,$B$1) -> 0 | G13: =SUMIFS(Transactions!$E:$E,Transactions!$G:$G,$B13,Transactions!$H:$H,$C13,Transactions!$J:$J,G$11,Transactions!$K:$K,$B$1) -> 0 | H13: =SUMIFS(Transactions!$E:$E,Transactions!$G:$G,$B13,Transactions!$H:$H,$C13,Transactions!$J:$J,H$11,Transactions!$K:$K,$B$1) -> 0 | I13: =SUMIFS(Transactions!$E:$E,Transactions!$G:$G,$B13,Transactions!$H:$H,$C13,Transactions!$J:$J,I$11,Transactions!$K:$K,$B$1) -> 0 | J13: =SUMIFS(Transactions!$E:$E,Transactions!$G:$G,$B13,Transactions!$H:$H,$C13,Transactions!$J:$J,J$11,Transactions!$K:$K,$B$1) -> 0 | K13: =SUMIFS(Transactions!$E:$E,Transactions!$G:$G,$B13,Transactions!$H:$H,$C13,Transactions!$J:$J,K$11,Transactions!$K:$K,$B$1) -> 0 | L13: =SUMIFS(Transactions!$E:$E,Transactions!$G:$G,$B13,Transactions!$H:$H,$C13,Transactions!$J:$J,L$11,Transactions!$K:$K,$B$1) -> 0 | ... P13: =SUMIFS(Transactions!$E:$E,Transactions!$G:$G,$B13,Transactions!$H:$H,$C13,Transactions!$J:$J,P$11,Transactions!$K:$K,$B$1) -> 0 | Q13: =SUM(E13:P13) -> 0 | R13: =D13*12 -> 2520
A14: 3 | B14: Home Expenses | C14: Electricity and Water Bill | D14: 500 | E14: =SUMIFS(Transactions!$E:$E,Transactions!$G:$G,$B14,Transactions!$H:$H,$C14,Transactions!$J:$J,E$11,Transactions!$K:$K,$B$1) -> 0 | F14: =SUMIFS(Transactions!$E:$E,Transactions!$G:$G,$B14,Transactions!$H:$H,$C14,Transactions!$J:$J,F$11,Transactions!$K:$K,$B$1) -> 0 | G14: =SUMIFS(Transactions!$E:$E,Transactions!$G:$G,$B14,Transactions!$H:$H,$C14,Transactions!$J:$J,G$11,Transactions!$K:$K,$B$1) -> 0 | H14: =SUMIFS(Transactions!$E:$E,Transactions!$G:$G,$B14,Transactions!$H:$H,$C14,Transactions!$J:$J,H$11,Transactions!$K:$K,$B$1) -> 0 | I14: =SUMIFS(Transactions!$E:$E,Transactions!$G:$G,$B14,Transactions!$H:$H,$C14,Transactions!$J:$J,I$11,Transactions!$K:$K,$B$1) -> 0 | J14: =SUMIFS(Transactions!$E:$E,Transactions!$G:$G,$B14,Transactions!$H:$H,$C14,Transactions!$J:$J,J$11,Transactions!$K:$K,$B$1) -> 0 | K14: =SUMIFS(Transactions!$E:$E,Transactions!$G:$G,$B14,Transactions!$H:$H,$C14,Transactions!$J:$J,K$11,Transactions!$K:$K,$B$1) -> 0 | L14: =SUMIFS(Transactions!$E:$E,Transactions!$G:$G,$B14,Transactions!$H:$H,$C14,Transactions!$J:$J,L$11,Transactions!$K:$K,$B$1) -> 0 | ... P14: =SUMIFS(Transactions!$E:$E,Transactions!$G:$G,$B14,Transactions!$H:$H,$C14,Transactions!$J:$J,P$11,Transactions!$K:$K,$B$1) -> 0 | Q14: =SUM(E14:P14) -> 0 | R14: =D14*12 -> 6000
A15: 4 | B15: Home Expenses | C15: Gas Bill | D15: 30 | E15: =SUMIFS(Transactions!$E:$E,Transactions!$G:$G,$B15,Transactions!$H:$H,$C15,Transactions!$J:$J,E$11,Transactions!$K:$K,$B$1) -> 0 | F15: =SUMIFS(Transactions!$E:$E,Transactions!$G:$G,$B15,Transactions!$H:$H,$C15,Transactions!$J:$J,F$11,Transactions!$K:$K,$B$1) -> 0 | G15: =SUMIFS(Transactions!$E:$E,Transactions!$G:$G,$B15,Transactions!$H:$H,$C15,Transactions!$J:$J,G$11,Transactions!$K:$K,$B$1) -> 0 | H15: =SUMIFS(Transactions!$E:$E,Transactions!$G:$G,$B15,Transactions!$H:$H,$C15,Transactions!$J:$J,H$11,Transactions!$K:$K,$B$1) -> 0 | I15: =SUMIFS(Transactions!$E:$E,Transactions!$G:$G,$B15,Transactions!$H:$H,$C15,Transactions!$J:$J,I$11,Transactions!$K:$K,$B$1) -> 0 | J15: =SUMIFS(Transactions!$E:$E,Transactions!$G:$G,$B15,Transactions!$H:$H,$C15,Transactions!$J:$J,J$11,Transactions!$K:$K,$B$1) -> 0 | K15: =SUMIFS(Transactions!$E:$E,Transactions!$G:$G,$B15,Transactions!$H:$H,$C15,Transactions!$J:$J,K$11,Transactions!$K:$K,$B$1) -> 0 | L15: =SUMIFS(Transactions!$E:$E,Transactions!$G:$G,$B15,Transactions!$H:$H,$C15,Transactions!$J:$J,L$11,Transactions!$K:$K,$B$1) -> 0 | ... P15: =SUMIFS(Transactions!$E:$E,Transactions!$G:$G,$B15,Transactions!$H:$H,$C15,Transactions!$J:$J,P$11,Transactions!$K:$K,$B$1) -> 0 | Q15: =SUM(E15:P15) -> 0 | R15: =D15*12 -> 360
A16: 5 | B16: Home Expenses | C16: Cable and Internet Bill | D16: 326.76 | E16: =SUMIFS(Transactions!$E:$E,Transactions!$G:$G,$B16,Transactions!$H:$H,$C16,Transactions!$J:$J,E$11,Transactions!$K:$K,$B$1) -> 0 | F16: =SUMIFS(Transactions!$E:$E,Transactions!$G:$G,$B16,Transactions!$H:$H,$C16,Transactions!$J:$J,F$11,Transactions!$K:$K,$B$1) -> 0 | G16: =SUMIFS(Transactions!$E:$E,Transactions!$G:$G,$B16,Transactions!$H:$H,$C16,Transactions!$J:$J,G$11,Transactions!$K:$K,$B$1) -> 0 | H16: =SUMIFS(Transactions!$E:$E,Transactions!$G:$G,$B16,Transactions!$H:$H,$C16,Transactions!$J:$J,H$11,Transactions!$K:$K,$B$1) -> 0 | I16: =SUMIFS(Transactions!$E:$E,Transactions!$G:$G,$B16,Transactions!$H:$H,$C16,Transactions!$J:$J,I$11,Transactions!$K:$K,$B$1) -> 0 | J16: =SUMIFS(Transactions!$E:$E,Transactions!$G:$G,$B16,Transactions!$H:$H,$C16,Transactions!$J:$J,J$11,Transactions!$K:$K,$B$1) -> 0 | K16: =SUMIFS(Transactions!$E:$E,Transactions!$G:$G,$B16,Transactions!$H:$H,$C16,Transactions!$J:$J,K$11,Transactions!$K:$K,$B$1) -> 0 | L16: =SUMIFS(Transactions!$E:$E,Transactions!$G:$G,$B16,Transactions!$H:$H,$C16,Transactions!$J:$J,L$11,Transactions!$K:$K,$B$1) -> 0 | ... P16: =SUMIFS(Transactions!$E:$E,Transactions!$G:$G,$B16,Transactions!$H:$H,$C16,Transactions!$J:$J,P$11,Transactions!$K:$K,$B$1) -> 0 | Q16: =SUM(E16:P16) -> 0 | R16: =D16*12 -> 3921.12
A17: 6 | B17: Home Expenses | C17: Cleaners | D17: 145 | E17: =SUMIFS(Transactions!$E:$E,Transactions!$G:$G,$B17,Transactions!$H:$H,$C17,Transactions!$J:$J,E$11,Transactions!$K:$K,$B$1) -> 0 | F17: =SUMIFS(Transactions!$E:$E,Transactions!$G:$G,$B17,Transactions!$H:$H,$C17,Transactions!$J:$J,F$11,Transactions!$K:$K,$B$1) -> 0 | G17: =SUMIFS(Transactions!$E:$E,Transactions!$G:$G,$B17,Transactions!$H:$H,$C17,Transactions!$J:$J,G$11,Transactions!$K:$K,$B$1) -> 0 | H17: =SUMIFS(Transactions!$E:$E,Transactions!$G:$G,$B17,Transactions!$H:$H,$C17,Transactions!$J:$J,H$11,Transactions!$K:$K,$B$1) -> 0 | I17: =SUMIFS(Transactions!$E:$E,Transactions!$G:$G,$B17,Transactions!$H:$H,$C17,Transactions!$J:$J,I$11,Transactions!$K:$K,$B$1) -> 0 | J17: =SUMIFS(Transactions!$E:$E,Transactions!$G:$G,$B17,Transactions!$H:$H,$C17,Transactions!$J:$J,J$11,Transactions!$K:$K,$B$1) -> 0 | K17: =SUMIFS(Transactions!$E:$E,Transactions!$G:$G,$B17,Transactions!$H:$H,$C17,Transactions!$J:$J,K$11,Transactions!$K:$K,$B$1) -> 0 | L17: =SUMIFS(Transactions!$E:$E,Transactions!$G:$G,$B17,Transactions!$H:$H,$C17,Transactions!$J:$J,L$11,Transactions!$K:$K,$B$1) -> 0 | ... P17: =SUMIFS(Transactions!$E:$E,Transactions!$G:$G,$B17,Transactions!$H:$H,$C17,Transactions!$J:$J,P$11,Transactions!$K:$K,$B$1) -> 0 | Q17: =SUM(E17:P17) -> 0 | R17: =D17*12 -> 1740
A18: 7 | B18: Home Expenses | C18: Home Supplies | D18: 1000 | E18: =SUMIFS(Transactions!$E:$E,Transactions!$G:$G,$B18,Transactions!$H:$H,$C18,Transactions!$J:$J,E$11,Transactions!$K:$K,$B$1) -> 0 | F18: =SUMIFS(Transactions!$E:$E,Transactions!$G:$G,$B18,Transactions!$H:$H,$C18,Transactions!$J:$J,F$11,Transactions!$K:$K,$B$1) -> 0 | G18: =SUMIFS(Transactions!$E:$E,Transactions!$G:$G,$B18,Transactions!$H:$H,$C18,Transactions!$J:$J,G$11,Transactions!$K:$K,$B$1) -> 0 | H18: =SUMIFS(Transactions!$E:$E,Transactions!$G:$G,$B18,Transactions!$H:$H,$C18,Transactions!$J:$J,H$11,Transactions!$K:$K,$B$1) -> 0 | I18: =SUMIFS(Transactions!$E:$E,Transactions!$G:$G,$B18,Transactions!$H:$H,$C18,Transactions!$J:$J,I$11,Transactions!$K:$K,$B$1) -> 0 | J18: =SUMIFS(Transactions!$E:$E,Transactions!$G:$G,$B18,Transactions!$H:$H,$C18,Transactions!$J:$J,J$11,Transactions!$K:$K,$B$1) -> 0 | K18: =SUMIFS(Transactions!$E:$E,Transactions!$G:$G,$B18,Transactions!$H:$H,$C18,Transactions!$J:$J,K$11,Transactions!$K:$K,$B$1) -> 0 | L18: =SUMIFS(Transactions!$E:$E,Transactions!$G:$G,$B18,Transactions!$H:$H,$C18,Transactions!$J:$J,L$11,Transactions!$K:$K,$B$1) -> 0 | ... P18: =SUMIFS(Transactions!$E:$E,Transactions!$G:$G,$B18,Transactions!$H:$H,$C18,Transactions!$J:$J,P$11,Transactions!$K:$K,$B$1) -> 0 | Q18: =SUM(E18:P18) -> 0 | R18: =D18*12 -> 12000
A19: 8 | B19: Home Expenses | C19: Water | D19: 35 | E19: =SUMIFS(Transactions!$E:$E,Transactions!$G:$G,$B19,Transactions!$H:$H,$C19,Transactions!$J:$J,E$11,Transactions!$K:$K,$B$1) -> 0 | F19: =SUMIFS(Transactions!$E:$E,Transactions!$G:$G,$B19,Transactions!$H:$H,$C19,Transactions!$J:$J,F$11,Transactions!$K:$K,$B$1) -> 0 | G19: =SUMIFS(Transactions!$E:$E,Transactions!$G:$G,$B19,Transactions!$H:$H,$C19,Transactions!$J:$J,G$11,Transactions!$K:$K,$B$1) -> 0 | H19: =SUMIFS(Transactions!$E:$E,Transactions!$G:$G,$B19,Transactions!$H:$H,$C19,Transactions!$J:$J,H$11,Transactions!$K:$K,$B$1) -> 0 | I19: =SUMIFS(Transactions!$E:$E,Transactions!$G:$G,$B19,Transactions!$H:$H,$C19,Transactions!$J:$J,I$11,Transactions!$K:$K,$B$1) -> 0 | J19: =SUMIFS(Transactions!$E:$E,Transactions!$G:$G,$B19,Transactions!$H:$H,$C19,Transactions!$J:$J,J$11,Transactions!$K:$K,$B$1) -> 0 | K19: =SUMIFS(Transactions!$E:$E,Transactions!$G:$G,$B19,Transactions!$H:$H,$C19,Transactions!$J:$J,K$11,Transactions!$K:$K,$B$1) -> 0 | L19: =SUMIFS(Transactions!$E:$E,Transactions!$G:$G,$B19,Transactions!$H:$H,$C19,Transactions!$J:$J,L$11,Transactions!$K:$K,$B$1) -> 0 | ... P19: =SUMIFS(Transactions!$E:$E,Transactions!$G:$G,$B19,Transactions!$H:$H,$C19,Transactions!$J:$J,P$11,Transactions!$K:$K,$B$1) -> 0 | Q19: =SUM(E19:P19) -> 0 | R19: =D19*12 -> 420
A20: 9 | B20: Home Expenses | C20: Laundry | D20: 50 | E20: =SUMIFS(Transactions!$E:$E,Transactions!$G:$G,$B20,Transactions!$H:$H,$C20,Transactions!$J:$J,E$11,Transactions!$K:$K,$B$1) -> 0 | F20: =SUMIFS(Transactions!$E:$E,Transactions!$G:$G,$B20,Transactions!$H:$H,$C20,Transactions!$J:$J,F$11,Transactions!$K:$K,$B$1) -> 0 | G20: =SUMIFS(Transactions!$E:$E,Transactions!$G:$G,$B20,Transactions!$H:$H,$C20,Transactions!$J:$J,G$11,Transactions!$K:$K,$B$1) -> 0 | H20: =SUMIFS(Transactions!$E:$E,Transactions!$G:$G,$B20,Transactions!$H:$H,$C20,Transactions!$J:$J,H$11,Transactions!$K:$K,$B$1) -> 0 | I20: =SUMIFS(Transactions!$E:$E,Transactions!$G:$G,$B20,Transactions!$H:$H,$C20,Transactions!$J:$J,I$11,Transactions!$K:$K,$B$1) -> 0 | J20: =SUMIFS(Transactions!$E:$E,Transactions!$G:$G,$B20,Transactions!$H:$H,$C20,Transactions!$J:$J,J$11,Transactions!$K:$K,$B$1) -> 0 | K20: =SUMIFS(Transactions!$E:$E,Transactions!$G:$G,$B20,Transactions!$H:$H,$C20,Transactions!$J:$J,K$11,Transactions!$K:$K,$B$1) -> 0 | L20: =SUMIFS(Transactions!$E:$E,Transactions!$G:$G,$B20,Transactions!$H:$H,$C20,Transactions!$J:$J,L$11,Transactions!$K:$K,$B$1) -> 0 | ... P20: =SUMIFS(Transactions!$E:$E,Transactions!$G:$G,$B20,Transactions!$H:$H,$C20,Transactions!$J:$J,P$11,Transactions!$K:$K,$B$1) -> 0 | Q20: =SUM(E20:P20) -> 0 | R20: =D20*12 -> 600
A21: 10 | B21: Home Expenses | C21: Food Delivery | D21: 600 | E21: =SUMIFS(Transactions!$E:$E,Transactions!$G:$G,$B21,Transactions!$H:$H,$C21,Transactions!$J:$J,E$11,Transactions!$K:$K,$B$1) -> 0 | F21: =SUMIFS(Transactions!$E:$E,Transactions!$G:$G,$B21,Transactions!$H:$H,$C21,Transactions!$J:$J,F$11,Transactions!$K:$K,$B$1) -> 0 | G21: =SUMIFS(Transactions!$E:$E,Transactions!$G:$G,$B21,Transactions!$H:$H,$C21,Transactions!$J:$J,G$11,Transactions!$K:$K,$B$1) -> 0 | H21: =SUMIFS(Transactions!$E:$E,Transactions!$G:$G,$B21,Transactions!$H:$H,$C21,Transactions!$J:$J,H$11,Transactions!$K:$K,$B$1) -> 0 | I21: =SUMIFS(Transactions!$E:$E,Transactions!$G:$G,$B21,Transactions!$H:$H,$C21,Transactions!$J:$J,I$11,Transactions!$K:$K,$B$1) -> 0 | J21: =SUMIFS(Transactions!$E:$E,Transactions!$G:$G,$B21,Transactions!$H:$H,$C21,Transactions!$J:$J,J$11,Transactions!$K:$K,$B$1) -> 0 | K21: =SUMIFS(Transactions!$E:$E,Transactions!$G:$G,$B21,Transactions!$H:$H,$C21,Transactions!$J:$J,K$11,Transactions!$K:$K,$B$1) -> 0 | L21: =SUMIFS(Transactions!$E:$E,Transactions!$G:$G,$B21,Transactions!$H:$H,$C21,Transactions!$J:$J,L$11,Transactions!$K:$K,$B$1) -> 245.5 | ... P21: =SUMIFS(Transactions!$E:$E,Transactions!$G:$G,$B21,Transactions!$H:$H,$C21,Transactions!$J:$J,P$11,Transactions!$K:$K,$B$1) -> 0 | Q21: =SUM(E21:P21) -> 245.5 | R21: =D21*12 -> 7200
A22: 11 | B22: Home Expenses | C22: Subscription | D22: 210 | E22: =SUMIFS(Transactions!$E:$E,Transactions!$G:$G,$B22,Transactions!$H:$H,$C22,Transactions!$J:$J,E$11,Transactions!$K:$K,$B$1) -> 0 | F22: =SUMIFS(Transactions!$E:$E,Transactions!$G:$G,$B22,Transactions!$H:$H,$C22,Transactions!$J:$J,F$11,Transactions!$K:$K,$B$1) -> 0 | G22: =SUMIFS(Transactions!$E:$E,Transactions!$G:$G,$B22,Transactions!$H:$H,$C22,Transactions!$J:$J,G$11,Transactions!$K:$K,$B$1) -> 0 | H22: =SUMIFS(Transactions!$E:$E,Transactions!$G:$G,$B22,Transactions!$H:$H,$C22,Transactions!$J:$J,H$11,Transactions!$K:$K,$B$1) -> 0 | I22: =SUMIFS(Transactions!$E:$E,Transactions!$G:$G,$B22,Transactions!$H:$H,$C22,Transactions!$J:$J,I$11,Transactions!$K:$K,$B$1) -> 0 | J22: =SUMIFS(Transactions!$E:$E,Transactions!$G:$G,$B22,Transactions!$H:$H,$C22,Transactions!$J:$J,J$11,Transactions!$K:$K,$B$1) -> 0 | K22: =SUMIFS(Transactions!$E:$E,Transactions!$G:$G,$B22,Transactions!$H:$H,$C22,Transactions!$J:$J,K$11,Transactions!$K:$K,$B$1) -> 0 | L22: =SUMIFS(Transactions!$E:$E,Transactions!$G:$G,$B22,Transactions!$H:$H,$C22,Transactions!$J:$J,L$11,Transactions!$K:$K,$B$1) -> 0 | ... P22: =SUMIFS(Transactions!$E:$E,Transactions!$G:$G,$B22,Transactions!$H:$H,$C22,Transactions!$J:$J,P$11,Transactions!$K:$K,$B$1) -> 0 | Q22: =SUM(E22:P22) -> 0 | R22: =D22*12 -> 2520
A23: 12 | B23: Home Expenses | C23: Meal Plan | D23: 1176 | E23: =SUMIFS(Transactions!$E:$E,Transactions!$G:$G,$B23,Transactions!$H:$H,$C23,Transactions!$J:$J,E$11,Transactions!$K:$K,$B$1) -> 0 | F23: =SUMIFS(Transactions!$E:$E,Transactions!$G:$G,$B23,Transactions!$H:$H,$C23,Transactions!$J:$J,F$11,Transactions!$K:$K,$B$1) -> 0 | G23: =SUMIFS(Transactions!$E:$E,Transactions!$G:$G,$B23,Transactions!$H:$H,$C23,Transactions!$J:$J,G$11,Transactions!$K:$K,$B$1) -> 0 | H23: =SUMIFS(Transactions!$E:$E,Transactions!$G:$G,$B23,Transactions!$H:$H,$C23,Transactions!$J:$J,H$11,Transactions!$K:$K,$B$1) -> 0 | I23: =SUMIFS(Transactions!$E:$E,Transactions!$G:$G,$B23,Transactions!$H:$H,$C23,Transactions!$J:$J,I$11,Transactions!$K:$K,$B$1) -> 0 | J23: =SUMIFS(Transactions!$E:$E,Transactions!$G:$G,$B23,Transactions!$H:$H,$C23,Transactions!$J:$J,J$11,Transactions!$K:$K,$B$1) -> 0 | K23: =SUMIFS(Transactions!$E:$E,Transactions!$G:$G,$B23,Transactions!$H:$H,$C23,Transactions!$J:$J,K$11,Transactions!$K:$K,$B$1) -> 0 | L23: =SUMIFS(Transactions!$E:$E,Transactions!$G:$G,$B23,Transactions!$H:$H,$C23,Transactions!$J:$J,L$11,Transactions!$K:$K,$B$1) -> 0 | ... P23: =SUMIFS(Transactions!$E:$E,Transactions!$G:$G,$B23,Transactions!$H:$H,$C23,Transactions!$J:$J,P$11,Transactions!$K:$K,$B$1) -> 0 | Q23: =SUM(E23:P23) -> 0 | R23: =D23*12 -> 14112
A24: 13 | B24: Home Expenses | C24: Other Home | D24: 0 | E24: =SUMIFS(Transactions!$E:$E,Transactions!$G:$G,$B24,Transactions!$H:$H,$C24,Transactions!$J:$J,E$11,Transactions!$K:$K,$B$1) -> 0 | F24: =SUMIFS(Transactions!$E:$E,Transactions!$G:$G,$B24,Transactions!$H:$H,$C24,Transactions!$J:$J,F$11,Transactions!$K:$K,$B$1) -> 0 | G24: =SUMIFS(Transactions!$E:$E,Transactions!$G:$G,$B24,Transactions!$H:$H,$C24,Transactions!$J:$J,G$11,Transactions!$K:$K,$B$1) -> 0 | H24: =SUMIFS(Transactions!$E:$E,Transactions!$G:$G,$B24,Transactions!$H:$H,$C24,Transactions!$J:$J,H$11,Transactions!$K:$K,$B$1) -> 0 | I24: =SUMIFS(Transactions!$E:$E,Transactions!$G:$G,$B24,Transactions!$H:$H,$C24,Transactions!$J:$J,I$11,Transactions!$K:$K,$B$1) -> 0 | J24: =SUMIFS(Transactions!$E:$E,Transactions!$G:$G,$B24,Transactions!$H:$H,$C24,Transactions!$J:$J,J$11,Transactions!$K:$K,$B$1) -> 0 | K24: =SUMIFS(Transactions!$E:$E,Transactions!$G:$G,$B24,Transactions!$H:$H,$C24,Transactions!$J:$J,K$11,Transactions!$K:$K,$B$1) -> 0 | L24: =SUMIFS(Transactions!$E:$E,Transactions!$G:$G,$B24,Transactions!$H:$H,$C24,Transactions!$J:$J,L$11,Transactions!$K:$K,$B$1) -> 0 | ... P24: =SUMIFS(Transactions!$E:$E,Transactions!$G:$G,$B24,Transactions!$H:$H,$C24,Transactions!$J:$J,P$11,Transactions!$K:$K,$B$1) -> 0 | Q24: =SUM(E24:P24) -> 0 | R24: =D24*12 -> 0
C25: Total Home Expenses | D25: =SUM(D12:D24) -> 7747.76 | E25: =SUM(E12:E24) -> 0 | F25: =SUM(F12:F24) -> 0 | G25: =SUM(G12:G24) -> 0 | H25: =SUM(H12:H24) -> 0 | I25: =SUM(I12:I24) -> 0 | J25: =SUM(J12:J24) -> 0 | K25: =SUM(K12:K24) -> 0 | ... R25: =SUM(R12:R24) -> 92973.12
A28: Index | B28: Category | C28: Transportation | D28: Monthly expected | E28: Jan | F28: Feb | G28: Mar | H28: Apr | I28: May | J28: Jun | K28: Jul | L28: Aug | M28: Sep | N28: Oct | O28: Nov | P28: Dec | Q28: Actual YTD | R28: Expected / year
A29: 1 | B29: Transportation | C29: Car Loan/Rent | D29: 1500 | E29: =SUMIFS(Transactions!$E:$E,Transactions!$G:$G,$B29,Transactions!$H:$H,$C29,Transactions!$J:$J,E$28,Transactions!$K:$K,$B$1) -> 0 | F29: =SUMIFS(Transactions!$E:$E,Transactions!$G:$G,$B29,Transactions!$H:$H,$C29,Transactions!$J:$J,F$28,Transactions!$K:$K,$B$1) -> 0 | G29: =SUMIFS(Transactions!$E:$E,Transactions!$G:$G,$B29,Transactions!$H:$H,$C29,Transactions!$J:$J,G$28,Transactions!$K:$K,$B$1) -> 0 | H29: =SUMIFS(Transactions!$E:$E,Transactions!$G:$G,$B29,Transactions!$H:$H,$C29,Transactions!$J:$J,H$28,Transactions!$K:$K,$B$1) -> 0 | I29: =SUMIFS(Transactions!$E:$E,Transactions!$G:$G,$B29,Transactions!$H:$H,$C29,Transactions!$J:$J,I$28,Transactions!$K:$K,$B$1) -> 0 | J29: =SUMIFS(Transactions!$E:$E,Transactions!$G:$G,$B29,Transactions!$H:$H,$C29,Transactions!$J:$J,J$28,Transactions!$K:$K,$B$1) -> 0 | K29: =SUMIFS(Transactions!$E:$E,Transactions!$G:$G,$B29,Transactions!$H:$H,$C29,Transactions!$J:$J,K$28,Transactions!$K:$K,$B$1) -> 0 | L29: =SUMIFS(Transactions!$E:$E,Transactions!$G:$G,$B29,Transactions!$H:$H,$C29,Transactions!$J:$J,L$28,Transactions!$K:$K,$B$1) -> 0 | ... P29: =SUMIFS(Transactions!$E:$E,Transactions!$G:$G,$B29,Transactions!$H:$H,$C29,Transactions!$J:$J,P$28,Transactions!$K:$K,$B$1) -> 0 | Q29: =SUM(E29:P29) -> 0 | R29: =D29*12 -> 18000
A30: 2 | B30: Transportation | C30: Fuel/Wash | D30: 400 | E30: =SUMIFS(Transactions!$E:$E,Transactions!$G:$G,$B30,Transactions!$H:$H,$C30,Transactions!$J:$J,E$28,Transactions!$K:$K,$B$1) -> 0 | F30: =SUMIFS(Transactions!$E:$E,Transactions!$G:$G,$B30,Transactions!$H:$H,$C30,Transactions!$J:$J,F$28,Transactions!$K:$K,$B$1) -> 0 | G30: =SUMIFS(Transactions!$E:$E,Transactions!$G:$G,$B30,Transactions!$H:$H,$C30,Transactions!$J:$J,G$28,Transactions!$K:$K,$B$1) -> 0 | H30: =SUMIFS(Transactions!$E:$E,Transactions!$G:$G,$B30,Transactions!$H:$H,$C30,Transactions!$J:$J,H$28,Transactions!$K:$K,$B$1) -> 0 | I30: =SUMIFS(Transactions!$E:$E,Transactions!$G:$G,$B30,Transactions!$H:$H,$C30,Transactions!$J:$J,I$28,Transactions!$K:$K,$B$1) -> 0 | J30: =SUMIFS(Transactions!$E:$E,Transactions!$G:$G,$B30,Transactions!$H:$H,$C30,Transactions!$J:$J,J$28,Transactions!$K:$K,$B$1) -> 0 | K30: =SUMIFS(Transactions!$E:$E,Transactions!$G:$G,$B30,Transactions!$H:$H,$C30,Transactions!$J:$J,K$28,Transactions!$K:$K,$B$1) -> 0 | L30: =SUMIFS(Transactions!$E:$E,Transactions!$G:$G,$B30,Transactions!$H:$H,$C30,Transactions!$J:$J,L$28,Transactions!$K:$K,$B$1) -> 0 | ... P30: =SUMIFS(Transactions!$E:$E,Transactions!$G:$G,$B30,Transactions!$H:$H,$C30,Transactions!$J:$J,P$28,Transactions!$K:$K,$B$1) -> 0 | Q30: =SUM(E30:P30) -> 0 | R30: =D30*12 -> 4800
A31: 3 | B31: Transportation | C31: Maintenance | D31: 100 | E31: =SUMIFS(Transactions!$E:$E,Transactions!$G:$G,$B31,Transactions!$H:$H,$C31,Transactions!$J:$J,E$28,Transactions!$K:$K,$B$1) -> 0 | F31: =SUMIFS(Transactions!$E:$E,Transactions!$G:$G,$B31,Transactions!$H:$H,$C31,Transactions!$J:$J,F$28,Transactions!$K:$K,$B$1) -> 0 | G31: =SUMIFS(Transactions!$E:$E,Transactions!$G:$G,$B31,Transactions!$H:$H,$C31,Transactions!$J:$J,G$28,Transactions!$K:$K,$B$1) -> 0 | H31: =SUMIFS(Transactions!$E:$E,Transactions!$G:$G,$B31,Transactions!$H:$H,$C31,Transactions!$J:$J,H$28,Transactions!$K:$K,$B$1) -> 0 | I31: =SUMIFS(Transactions!$E:$E,Transactions!$G:$G,$B31,Transactions!$H:$H,$C31,Transactions!$J:$J,I$28,Transactions!$K:$K,$B$1) -> 0 | J31: =SUMIFS(Transactions!$E:$E,Transactions!$G:$G,$B31,Transactions!$H:$H,$C31,Transactions!$J:$J,J$28,Transactions!$K:$K,$B$1) -> 0 | K31: =SUMIFS(Transactions!$E:$E,Transactions!$G:$G,$B31,Transactions!$H:$H,$C31,Transactions!$J:$J,K$28,Transactions!$K:$K,$B$1) -> 0 | L31: =SUMIFS(Transactions!$E:$E,Transactions!$G:$G,$B31,Transactions!$H:$H,$C31,Transactions!$J:$J,L$28,Transactions!$K:$K,$B$1) -> 0 | ... P31: =SUMIFS(Transactions!$E:$E,Transactions!$G:$G,$B31,Transactions!$H:$H,$C31,Transactions!$J:$J,P$28,Transactions!$K:$K,$B$1) -> 0 | Q31: =SUM(E31:P31) -> 0 | R31: =D31*12 -> 1200
A32: 4 | B32: Transportation | C32: Insurance | D32: 210 | E32: =SUMIFS(Transactions!$E:$E,Transactions!$G:$G,$B32,Transactions!$H:$H,$C32,Transactions!$J:$J,E$28,Transactions!$K:$K,$B$1) -> 0 | F32: =SUMIFS(Transactions!$E:$E,Transactions!$G:$G,$B32,Transactions!$H:$H,$C32,Transactions!$J:$J,F$28,Transactions!$K:$K,$B$1) -> 0 | G32: =SUMIFS(Transactions!$E:$E,Transactions!$G:$G,$B32,Transactions!$H:$H,$C32,Transactions!$J:$J,G$28,Transactions!$K:$K,$B$1) -> 0 | H32: =SUMIFS(Transactions!$E:$E,Transactions!$G:$G,$B32,Transactions!$H:$H,$C32,Transactions!$J:$J,H$28,Transactions!$K:$K,$B$1) -> 0 | I32: =SUMIFS(Transactions!$E:$E,Transactions!$G:$G,$B32,Transactions!$H:$H,$C32,Transactions!$J:$J,I$28,Transactions!$K:$K,$B$1) -> 0 | J32: =SUMIFS(Transactions!$E:$E,Transactions!$G:$G,$B32,Transactions!$H:$H,$C32,Transactions!$J:$J,J$28,Transactions!$K:$K,$B$1) -> 0 | K32: =SUMIFS(Transactions!$E:$E,Transactions!$G:$G,$B32,Transactions!$H:$H,$C32,Transactions!$J:$J,K$28,Transactions!$K:$K,$B$1) -> 0 | L32: =SUMIFS(Transactions!$E:$E,Transactions!$G:$G,$B32,Transactions!$H:$H,$C32,Transactions!$J:$J,L$28,Transactions!$K:$K,$B$1) -> 0 | ... P32: =SUMIFS(Transactions!$E:$E,Transactions!$G:$G,$B32,Transactions!$H:$H,$C32,Transactions!$J:$J,P$28,Transactions!$K:$K,$B$1) -> 0 | Q32: =SUM(E32:P32) -> 0 | R32: =D32*12 -> 2520
A33: 5 | B33: Transportation | C33: Salik and Parking | D33: 50 | E33: =SUMIFS(Transactions!$E:$E,Transactions!$G:$G,$B33,Transactions!$H:$H,$C33,Transactions!$J:$J,E$28,Transactions!$K:$K,$B$1) -> 0 | F33: =SUMIFS(Transactions!$E:$E,Transactions!$G:$G,$B33,Transactions!$H:$H,$C33,Transactions!$J:$J,F$28,Transactions!$K:$K,$B$1) -> 0 | G33: =SUMIFS(Transactions!$E:$E,Transactions!$G:$G,$B33,Transactions!$H:$H,$C33,Transactions!$J:$J,G$28,Transactions!$K:$K,$B$1) -> 0 | H33: =SUMIFS(Transactions!$E:$E,Transactions!$G:$G,$B33,Transactions!$H:$H,$C33,Transactions!$J:$J,H$28,Transactions!$K:$K,$B$1) -> 0 | I33: =SUMIFS(Transactions!$E:$E,Transactions!$G:$G,$B33,Transactions!$H:$H,$C33,Transactions!$J:$J,I$28,Transactions!$K:$K,$B$1) -> 0 | J33: =SUMIFS(Transactions!$E:$E,Transactions!$G:$G,$B33,Transactions!$H:$H,$C33,Transactions!$J:$J,J$28,Transactions!$K:$K,$B$1) -> 0 | K33: =SUMIFS(Transactions!$E:$E,Transactions!$G:$G,$B33,Transactions!$H:$H,$C33,Transactions!$J:$J,K$28,Transactions!$K:$K,$B$1) -> 0 | L33: =SUMIFS(Transactions!$E:$E,Transactions!$G:$G,$B33,Transactions!$H:$H,$C33,Transactions!$J:$J,L$28,Transactions!$K:$K,$B$1) -> 0 | ... P33: =SUMIFS(Transactions!$E:$E,Transactions!$G:$G,$B33,Transactions!$H:$H,$C33,Transactions!$J:$J,P$28,Transactions!$K:$K,$B$1) -> 0 | Q33: =SUM(E33:P33) -> 0 | R33: =D33*12 -> 600
A34: 6 | B34: Transportation | C34: Repairs | D34: 0 | E34: =SUMIFS(Transactions!$E:$E,Transactions!$G:$G,$B34,Transactions!$H:$H,$C34,Transactions!$J:$J,E$28,Transactions!$K:$K,$B$1) -> 0 | F34: =SUMIFS(Transactions!$E:$E,Transactions!$G:$G,$B34,Transactions!$H:$H,$C34,Transactions!$J:$J,F$28,Transactions!$K:$K,$B$1) -> 0 | G34: =SUMIFS(Transactions!$E:$E,Transactions!$G:$G,$B34,Transactions!$H:$H,$C34,Transactions!$J:$J,G$28,Transactions!$K:$K,$B$1) -> 0 | H34: =SUMIFS(Transactions!$E:$E,Transactions!$G:$G,$B34,Transactions!$H:$H,$C34,Transactions!$J:$J,H$28,Transactions!$K:$K,$B$1) -> 0 | I34: =SUMIFS(Transactions!$E:$E,Transactions!$G:$G,$B34,Transactions!$H:$H,$C34,Transactions!$J:$J,I$28,Transactions!$K:$K,$B$1) -> 0 | J34: =SUMIFS(Transactions!$E:$E,Transactions!$G:$G,$B34,Transactions!$H:$H,$C34,Transactions!$J:$J,J$28,Transactions!$K:$K,$B$1) -> 0 | K34: =SUMIFS(Transactions!$E:$E,Transactions!$G:$G,$B34,Transactions!$H:$H,$C34,Transactions!$J:$J,K$28,Transactions!$K:$K,$B$1) -> 0 | L34: =SUMIFS(Transactions!$E:$E,Transactions!$G:$G,$B34,Transactions!$H:$H,$C34,Transactions!$J:$J,L$28,Transactions!$K:$K,$B$1) -> 0 | ... P34: =SUMIFS(Transactions!$E:$E,Transactions!$G:$G,$B34,Transactions!$H:$H,$C34,Transactions!$J:$J,P$28,Transactions!$K:$K,$B$1) -> 0 | Q34: =SUM(E34:P34) -> 0 | R34: =D34*12 -> 0
A35: 7 | B35: Transportation | C35: Registration | D35: 50 | E35: =SUMIFS(Transactions!$E:$E,Transactions!$G:$G,$B35,Transactions!$H:$H,$C35,Transactions!$J:$J,E$28,Transactions!$K:$K,$B$1) -> 0 | F35: =SUMIFS(Transactions!$E:$E,Transactions!$G:$G,$B35,Transactions!$H:$H,$C35,Transactions!$J:$J,F$28,Transactions!$K:$K,$B$1) -> 0 | G35: =SUMIFS(Transactions!$E:$E,Transactions!$G:$G,$B35,Transactions!$H:$H,$C35,Transactions!$J:$J,G$28,Transactions!$K:$K,$B$1) -> 0 | H35: =SUMIFS(Transactions!$E:$E,Transactions!$G:$G,$B35,Transactions!$H:$H,$C35,Transactions!$J:$J,H$28,Transactions!$K:$K,$B$1) -> 0 | I35: =SUMIFS(Transactions!$E:$E,Transactions!$G:$G,$B35,Transactions!$H:$H,$C35,Transactions!$J:$J,I$28,Transactions!$K:$K,$B$1) -> 0 | J35: =SUMIFS(Transactions!$E:$E,Transactions!$G:$G,$B35,Transactions!$H:$H,$C35,Transactions!$J:$J,J$28,Transactions!$K:$K,$B$1) -> 0 | K35: =SUMIFS(Transactions!$E:$E,Transactions!$G:$G,$B35,Transactions!$H:$H,$C35,Transactions!$J:$J,K$28,Transactions!$K:$K,$B$1) -> 0 | L35: =SUMIFS(Transactions!$E:$E,Transactions!$G:$G,$B35,Transactions!$H:$H,$C35,Transactions!$J:$J,L$28,Transactions!$K:$K,$B$1) -> 0 | ... P35: =SUMIFS(Transactions!$E:$E,Transactions!$G:$G,$B35,Transactions!$H:$H,$C35,Transactions!$J:$J,P$28,Transactions!$K:$K,$B$1) -> 0 | Q35: =SUM(E35:P35) -> 0 | R35: =D35*12 -> 600
A36: 8 | B36: Transportation | C36: License | D36: 0 | E36: =SUMIFS(Transactions!$E:$E,Transactions!$G:$G,$B36,Transactions!$H:$H,$C36,Transactions!$J:$J,E$28,Transactions!$K:$K,$B$1) -> 0 | F36: =SUMIFS(Transactions!$E:$E,Transactions!$G:$G,$B36,Transactions!$H:$H,$C36,Transactions!$J:$J,F$28,Transactions!$K:$K,$B$1) -> 0 | G36: =SUMIFS(Transactions!$E:$E,Transactions!$G:$G,$B36,Transactions!$H:$H,$C36,Transactions!$J:$J,G$28,Transactions!$K:$K,$B$1) -> 0 | H36: =SUMIFS(Transactions!$E:$E,Transactions!$G:$G,$B36,Transactions!$H:$H,$C36,Transactions!$J:$J,H$28,Transactions!$K:$K,$B$1) -> 0 | I36: =SUMIFS(Transactions!$E:$E,Transactions!$G:$G,$B36,Transactions!$H:$H,$C36,Transactions!$J:$J,I$28,Transactions!$K:$K,$B$1) -> 0 | J36: =SUMIFS(Transactions!$E:$E,Transactions!$G:$G,$B36,Transactions!$H:$H,$C36,Transactions!$J:$J,J$28,Transactions!$K:$K,$B$1) -> 0 | K36: =SUMIFS(Transactions!$E:$E,Transactions!$G:$G,$B36,Transactions!$H:$H,$C36,Transactions!$J:$J,K$28,Transactions!$K:$K,$B$1) -> 0 | L36: =SUMIFS(Transactions!$E:$E,Transactions!$G:$G,$B36,Transactions!$H:$H,$C36,Transactions!$J:$J,L$28,Transactions!$K:$K,$B$1) -> 0 | ... P36: =SUMIFS(Transactions!$E:$E,Transactions!$G:$G,$B36,Transactions!$H:$H,$C36,Transactions!$J:$J,P$28,Transactions!$K:$K,$B$1) -> 0 | Q36: =SUM(E36:P36) -> 0 | R36: =D36*12 -> 0
A37: 9 | B37: Transportation | C37: Others Transportation | D37: 0 | E37: =SUMIFS(Transactions!$E:$E,Transactions!$G:$G,$B37,Transactions!$H:$H,$C37,Transactions!$J:$J,E$28,Transactions!$K:$K,$B$1) -> 0 | F37: =SUMIFS(Transactions!$E:$E,Transactions!$G:$G,$B37,Transactions!$H:$H,$C37,Transactions!$J:$J,F$28,Transactions!$K:$K,$B$1) -> 0 | G37: =SUMIFS(Transactions!$E:$E,Transactions!$G:$G,$B37,Transactions!$H:$H,$C37,Transactions!$J:$J,G$28,Transactions!$K:$K,$B$1) -> 0 | H37: =SUMIFS(Transactions!$E:$E,Transactions!$G:$G,$B37,Transactions!$H:$H,$C37,Transactions!$J:$J,H$28,Transactions!$K:$K,$B$1) -> 0 | I37: =SUMIFS(Transactions!$E:$E,Transactions!$G:$G,$B37,Transactions!$H:$H,$C37,Transactions!$J:$J,I$28,Transactions!$K:$K,$B$1) -> 0 | J37: =SUMIFS(Transactions!$E:$E,Transactions!$G:$G,$B37,Transactions!$H:$H,$C37,Transactions!$J:$J,J$28,Transactions!$K:$K,$B$1) -> 0 | K37: =SUMIFS(Transactions!$E:$E,Transactions!$G:$G,$B37,Transactions!$H:$H,$C37,Transactions!$J:$J,K$28,Transactions!$K:$K,$B$1) -> 0 | L37: =SUMIFS(Transactions!$E:$E,Transactions!$G:$G,$B37,Transactions!$H:$H,$C37,Transactions!$J:$J,L$28,Transactions!$K:$K,$B$1) -> 0 | ... P37: =SUMIFS(Transactions!$E:$E,Transactions!$G:$G,$B37,Transactions!$H:$H,$C37,Transactions!$J:$J,P$28,Transactions!$K:$K,$B$1) -> 0 | Q37: =SUM(E37:P37) -> 0 | R37: =D37*12 -> 0
C38: Total Transportation | D38: =SUM(D29:D37) -> 2310 | E38: =SUM(E29:E37) -> 0 | F38: =SUM(F29:F37) -> 0 | G38: =SUM(G29:G37) -> 0 | H38: =SUM(H29:H37) -> 0 | I38: =SUM(I29:I37) -> 0 | J38: =SUM(J29:J37) -> 0 | K38: =SUM(K29:K37) -> 0 | ... R38: =SUM(R29:R37) -> 27720
A41: Index | B41: Category | C41: Personal | D41: Monthly expected | E41: Jan | F41: Feb | G41: Mar | H41: Apr | I41: May | J41: Jun | K41: Jul | L41: Aug | M41: Sep | N41: Oct | O41: Nov | P41: Dec | Q41: Actual YTD | R41: Expected / year
A42: 1 | B42: Personal | C42: Gym | D42: 600 | E42: =SUMIFS(Transactions!$E:$E,Transactions!$G:$G,$B42,Transactions!$H:$H,$C42,Transactions!$J:$J,E$41,Transactions!$K:$K,$B$1) -> 0 | F42: =SUMIFS(Transactions!$E:$E,Transactions!$G:$G,$B42,Transactions!$H:$H,$C42,Transactions!$J:$J,F$41,Transactions!$K:$K,$B$1) -> 0 | G42: =SUMIFS(Transactions!$E:$E,Transactions!$G:$G,$B42,Transactions!$H:$H,$C42,Transactions!$J:$J,G$41,Transactions!$K:$K,$B$1) -> 0 | H42: =SUMIFS(Transactions!$E:$E,Transactions!$G:$G,$B42,Transactions!$H:$H,$C42,Transactions!$J:$J,H$41,Transactions!$K:$K,$B$1) -> 0 | I42: =SUMIFS(Transactions!$E:$E,Transactions!$G:$G,$B42,Transactions!$H:$H,$C42,Transactions!$J:$J,I$41,Transactions!$K:$K,$B$1) -> 0 | J42: =SUMIFS(Transactions!$E:$E,Transactions!$G:$G,$B42,Transactions!$H:$H,$C42,Transactions!$J:$J,J$41,Transactions!$K:$K,$B$1) -> 0 | K42: =SUMIFS(Transactions!$E:$E,Transactions!$G:$G,$B42,Transactions!$H:$H,$C42,Transactions!$J:$J,K$41,Transactions!$K:$K,$B$1) -> 0 | L42: =SUMIFS(Transactions!$E:$E,Transactions!$G:$G,$B42,Transactions!$H:$H,$C42,Transactions!$J:$J,L$41,Transactions!$K:$K,$B$1) -> 0 | ... P42: =SUMIFS(Transactions!$E:$E,Transactions!$G:$G,$B42,Transactions!$H:$H,$C42,Transactions!$J:$J,P$41,Transactions!$K:$K,$B$1) -> 0 | Q42: =SUM(E42:P42) -> 0 | R42: =D42*12 -> 7200
A43: 2 | B43: Personal | C43: Salon | D43: 600 | E43: =SUMIFS(Transactions!$E:$E,Transactions!$G:$G,$B43,Transactions!$H:$H,$C43,Transactions!$J:$J,E$41,Transactions!$K:$K,$B$1) -> 0 | F43: =SUMIFS(Transactions!$E:$E,Transactions!$G:$G,$B43,Transactions!$H:$H,$C43,Transactions!$J:$J,F$41,Transactions!$K:$K,$B$1) -> 0 | G43: =SUMIFS(Transactions!$E:$E,Transactions!$G:$G,$B43,Transactions!$H:$H,$C43,Transactions!$J:$J,G$41,Transactions!$K:$K,$B$1) -> 0 | H43: =SUMIFS(Transactions!$E:$E,Transactions!$G:$G,$B43,Transactions!$H:$H,$C43,Transactions!$J:$J,H$41,Transactions!$K:$K,$B$1) -> 0 | I43: =SUMIFS(Transactions!$E:$E,Transactions!$G:$G,$B43,Transactions!$H:$H,$C43,Transactions!$J:$J,I$41,Transactions!$K:$K,$B$1) -> 0 | J43: =SUMIFS(Transactions!$E:$E,Transactions!$G:$G,$B43,Transactions!$H:$H,$C43,Transactions!$J:$J,J$41,Transactions!$K:$K,$B$1) -> 0 | K43: =SUMIFS(Transactions!$E:$E,Transactions!$G:$G,$B43,Transactions!$H:$H,$C43,Transactions!$J:$J,K$41,Transactions!$K:$K,$B$1) -> 0 | L43: =SUMIFS(Transactions!$E:$E,Transactions!$G:$G,$B43,Transactions!$H:$H,$C43,Transactions!$J:$J,L$41,Transactions!$K:$K,$B$1) -> 0 | ... P43: =SUMIFS(Transactions!$E:$E,Transactions!$G:$G,$B43,Transactions!$H:$H,$C43,Transactions!$J:$J,P$41,Transactions!$K:$K,$B$1) -> 0 | Q43: =SUM(E43:P43) -> 0 | R43: =D43*12 -> 7200
A44: 3 | B44: Personal | C44: Clothing | D44: 450 | E44: =SUMIFS(Transactions!$E:$E,Transactions!$G:$G,$B44,Transactions!$H:$H,$C44,Transactions!$J:$J,E$41,Transactions!$K:$K,$B$1) -> 0 | F44: =SUMIFS(Transactions!$E:$E,Transactions!$G:$G,$B44,Transactions!$H:$H,$C44,Transactions!$J:$J,F$41,Transactions!$K:$K,$B$1) -> 0 | G44: =SUMIFS(Transactions!$E:$E,Transactions!$G:$G,$B44,Transactions!$H:$H,$C44,Transactions!$J:$J,G$41,Transactions!$K:$K,$B$1) -> 0 | H44: =SUMIFS(Transactions!$E:$E,Transactions!$G:$G,$B44,Transactions!$H:$H,$C44,Transactions!$J:$J,H$41,Transactions!$K:$K,$B$1) -> 0 | I44: =SUMIFS(Transactions!$E:$E,Transactions!$G:$G,$B44,Transactions!$H:$H,$C44,Transactions!$J:$J,I$41,Transactions!$K:$K,$B$1) -> 0 | J44: =SUMIFS(Transactions!$E:$E,Transactions!$G:$G,$B44,Transactions!$H:$H,$C44,Transactions!$J:$J,J$41,Transactions!$K:$K,$B$1) -> 0 | K44: =SUMIFS(Transactions!$E:$E,Transactions!$G:$G,$B44,Transactions!$H:$H,$C44,Transactions!$J:$J,K$41,Transactions!$K:$K,$B$1) -> 0 | L44: =SUMIFS(Transactions!$E:$E,Transactions!$G:$G,$B44,Transactions!$H:$H,$C44,Transactions!$J:$J,L$41,Transactions!$K:$K,$B$1) -> 0 | ... P44: =SUMIFS(Transactions!$E:$E,Transactions!$G:$G,$B44,Transactions!$H:$H,$C44,Transactions!$J:$J,P$41,Transactions!$K:$K,$B$1) -> 0 | Q44: =SUM(E44:P44) -> 0 | R44: =D44*12 -> 5400
A45: 4 | B45: Personal | C45: Self Care | D45: 300 | E45: =SUMIFS(Transactions!$E:$E,Transactions!$G:$G,$B45,Transactions!$H:$H,$C45,Transactions!$J:$J,E$41,Transactions!$K:$K,$B$1) -> 0 | F45: =SUMIFS(Transactions!$E:$E,Transactions!$G:$G,$B45,Transactions!$H:$H,$C45,Transactions!$J:$J,F$41,Transactions!$K:$K,$B$1) -> 0 | G45: =SUMIFS(Transactions!$E:$E,Transactions!$G:$G,$B45,Transactions!$H:$H,$C45,Transactions!$J:$J,G$41,Transactions!$K:$K,$B$1) -> 0 | H45: =SUMIFS(Transactions!$E:$E,Transactions!$G:$G,$B45,Transactions!$H:$H,$C45,Transactions!$J:$J,H$41,Transactions!$K:$K,$B$1) -> 0 | I45: =SUMIFS(Transactions!$E:$E,Transactions!$G:$G,$B45,Transactions!$H:$H,$C45,Transactions!$J:$J,I$41,Transactions!$K:$K,$B$1) -> 0 | J45: =SUMIFS(Transactions!$E:$E,Transactions!$G:$G,$B45,Transactions!$H:$H,$C45,Transactions!$J:$J,J$41,Transactions!$K:$K,$B$1) -> 0 | K45: =SUMIFS(Transactions!$E:$E,Transactions!$G:$G,$B45,Transactions!$H:$H,$C45,Transactions!$J:$J,K$41,Transactions!$K:$K,$B$1) -> 0 | L45: =SUMIFS(Transactions!$E:$E,Transactions!$G:$G,$B45,Transactions!$H:$H,$C45,Transactions!$J:$J,L$41,Transactions!$K:$K,$B$1) -> 0 | ... P45: =SUMIFS(Transactions!$E:$E,Transactions!$G:$G,$B45,Transactions!$H:$H,$C45,Transactions!$J:$J,P$41,Transactions!$K:$K,$B$1) -> 0 | Q45: =SUM(E45:P45) -> 0 | R45: =D45*12 -> 3600
A46: 5 | B46: Personal | C46: Outing | D46: 600 | E46: =SUMIFS(Transactions!$E:$E,Transactions!$G:$G,$B46,Transactions!$H:$H,$C46,Transactions!$J:$J,E$41,Transactions!$K:$K,$B$1) -> 0 | F46: =SUMIFS(Transactions!$E:$E,Transactions!$G:$G,$B46,Transactions!$H:$H,$C46,Transactions!$J:$J,F$41,Transactions!$K:$K,$B$1) -> 0 | G46: =SUMIFS(Transactions!$E:$E,Transactions!$G:$G,$B46,Transactions!$H:$H,$C46,Transactions!$J:$J,G$41,Transactions!$K:$K,$B$1) -> 0 | H46: =SUMIFS(Transactions!$E:$E,Transactions!$G:$G,$B46,Transactions!$H:$H,$C46,Transactions!$J:$J,H$41,Transactions!$K:$K,$B$1) -> 0 | I46: =SUMIFS(Transactions!$E:$E,Transactions!$G:$G,$B46,Transactions!$H:$H,$C46,Transactions!$J:$J,I$41,Transactions!$K:$K,$B$1) -> 0 | J46: =SUMIFS(Transactions!$E:$E,Transactions!$G:$G,$B46,Transactions!$H:$H,$C46,Transactions!$J:$J,J$41,Transactions!$K:$K,$B$1) -> 0 | K46: =SUMIFS(Transactions!$E:$E,Transactions!$G:$G,$B46,Transactions!$H:$H,$C46,Transactions!$J:$J,K$41,Transactions!$K:$K,$B$1) -> 0 | L46: =SUMIFS(Transactions!$E:$E,Transactions!$G:$G,$B46,Transactions!$H:$H,$C46,Transactions!$J:$J,L$41,Transactions!$K:$K,$B$1) -> 0 | ... P46: =SUMIFS(Transactions!$E:$E,Transactions!$G:$G,$B46,Transactions!$H:$H,$C46,Transactions!$J:$J,P$41,Transactions!$K:$K,$B$1) -> 0 | Q46: =SUM(E46:P46) -> 0 | R46: =D46*12 -> 7200
...

Sheet Budget vs Actual
A1: Budget vs Actual
A3: Month | B3: Aug | C3: Year | D3: 2026 | E3: ← type any month
A5: Category | B5: Segment | C5: Budget | D5: Spent | E5: Left | F5: Used | G5: Status
A6: Home Expenses | B6: Mortgage/Rent | C6: =SUMIFS(Monthly!$D:$D,Monthly!$B:$B,$A6,Monthly!$C:$C,$B6) -> 3465 | D6: =SUMIFS(Transactions!$E:$E,Transactions!$G:$G,$A6,Transactions!$H:$H,$B6,Transactions!$J:$J,$B$3,Transactions!$K:$K,$D$3) -> 0 | E6: =C6-D6 -> 3465 | F6: =IFERROR(D6/C6,0) -> 0 | G6: =IF(C6=0,IF(D6>0,"No budget","—"),IF(D6>C6,"OVER",IF(D6/C6>=0.9,"Close","OK"))) -> OK
A7: Home Expenses | B7: Phone Bills | C7: =SUMIFS(Monthly!$D:$D,Monthly!$B:$B,$A7,Monthly!$C:$C,$B7) -> 210 | D7: =SUMIFS(Transactions!$E:$E,Transactions!$G:$G,$A7,Transactions!$H:$H,$B7,Transactions!$J:$J,$B$3,Transactions!$K:$K,$D$3) -> 0 | E7: =C7-D7 -> 210 | F7: =IFERROR(D7/C7,0) -> 0 | G7: =IF(C7=0,IF(D7>0,"No budget","—"),IF(D7>C7,"OVER",IF(D7/C7>=0.9,"Close","OK"))) -> OK
A8: Home Expenses | B8: Electricity and Water Bill | C8: =SUMIFS(Monthly!$D:$D,Monthly!$B:$B,$A8,Monthly!$C:$C,$B8) -> 500 | D8: =SUMIFS(Transactions!$E:$E,Transactions!$G:$G,$A8,Transactions!$H:$H,$B8,Transactions!$J:$J,$B$3,Transactions!$K:$K,$D$3) -> 0 | E8: =C8-D8 -> 500 | F8: =IFERROR(D8/C8,0) -> 0 | G8: =IF(C8=0,IF(D8>0,"No budget","—"),IF(D8>C8,"OVER",IF(D8/C8>=0.9,"Close","OK"))) -> OK
A9: Home Expenses | B9: Gas Bill | C9: =SUMIFS(Monthly!$D:$D,Monthly!$B:$B,$A9,Monthly!$C:$C,$B9) -> 30 | D9: =SUMIFS(Transactions!$E:$E,Transactions!$G:$G,$A9,Transactions!$H:$H,$B9,Transactions!$J:$J,$B$3,Transactions!$K:$K,$D$3) -> 0 | E9: =C9-D9 -> 30 | F9: =IFERROR(D9/C9,0) -> 0 | G9: =IF(C9=0,IF(D9>0,"No budget","—"),IF(D9>C9,"OVER",IF(D9/C9>=0.9,"Close","OK"))) -> OK
A10: Home Expenses | B10: Cable and Internet Bill | C10: =SUMIFS(Monthly!$D:$D,Monthly!$B:$B,$A10,Monthly!$C:$C,$B10) -> 326.76 | D10: =SUMIFS(Transactions!$E:$E,Transactions!$G:$G,$A10,Transactions!$H:$H,$B10,Transactions!$J:$J,$B$3,Transactions!$K:$K,$D$3) -> 0 | E10: =C10-D10 -> 326.76 | F10: =IFERROR(D10/C10,0) -> 0 | G10: =IF(C10=0,IF(D10>0,"No budget","—"),IF(D10>C10,"OVER",IF(D10/C10>=0.9,"Close","OK"))) -> OK
A11: Home Expenses | B11: Cleaners | C11: =SUMIFS(Monthly!$D:$D,Monthly!$B:$B,$A11,Monthly!$C:$C,$B11) -> 145 | D11: =SUMIFS(Transactions!$E:$E,Transactions!$G:$G,$A11,Transactions!$H:$H,$B11,Transactions!$J:$J,$B$3,Transactions!$K:$K,$D$3) -> 0 | E11: =C11-D11 -> 145 | F11: =IFERROR(D11/C11,0) -> 0 | G11: =IF(C11=0,IF(D11>0,"No budget","—"),IF(D11>C11,"OVER",IF(D11/C11>=0.9,"Close","OK"))) -> OK
A12: Home Expenses | B12: Home Supplies | C12: =SUMIFS(Monthly!$D:$D,Monthly!$B:$B,$A12,Monthly!$C:$C,$B12) -> 1000 | D12: =SUMIFS(Transactions!$E:$E,Transactions!$G:$G,$A12,Transactions!$H:$H,$B12,Transactions!$J:$J,$B$3,Transactions!$K:$K,$D$3) -> 0 | E12: =C12-D12 -> 1000 | F12: =IFERROR(D12/C12,0) -> 0 | G12: =IF(C12=0,IF(D12>0,"No budget","—"),IF(D12>C12,"OVER",IF(D12/C12>=0.9,"Close","OK"))) -> OK
A13: Home Expenses | B13: Water | C13: =SUMIFS(Monthly!$D:$D,Monthly!$B:$B,$A13,Monthly!$C:$C,$B13) -> 35 | D13: =SUMIFS(Transactions!$E:$E,Transactions!$G:$G,$A13,Transactions!$H:$H,$B13,Transactions!$J:$J,$B$3,Transactions!$K:$K,$D$3) -> 0 | E13: =C13-D13 -> 35 | F13: =IFERROR(D13/C13,0) -> 0 | G13: =IF(C13=0,IF(D13>0,"No budget","—"),IF(D13>C13,"OVER",IF(D13/C13>=0.9,"Close","OK"))) -> OK
A14: Home Expenses | B14: Laundry | C14: =SUMIFS(Monthly!$D:$D,Monthly!$B:$B,$A14,Monthly!$C:$C,$B14) -> 50 | D14: =SUMIFS(Transactions!$E:$E,Transactions!$G:$G,$A14,Transactions!$H:$H,$B14,Transactions!$J:$J,$B$3,Transactions!$K:$K,$D$3) -> 0 | E14: =C14-D14 -> 50 | F14: =IFERROR(D14/C14,0) -> 0 | G14: =IF(C14=0,IF(D14>0,"No budget","—"),IF(D14>C14,"OVER",IF(D14/C14>=0.9,"Close","OK"))) -> OK
A15: Home Expenses | B15: Food Delivery | C15: =SUMIFS(Monthly!$D:$D,Monthly!$B:$B,$A15,Monthly!$C:$C,$B15) -> 600 | D15: =SUMIFS(Transactions!$E:$E,Transactions!$G:$G,$A15,Transactions!$H:$H,$B15,Transactions!$J:$J,$B$3,Transactions!$K:$K,$D$3) -> 245.5 | E15: =C15-D15 -> 354.5 | F15: =IFERROR(D15/C15,0) -> 0.40916667 | G15: =IF(C15=0,IF(D15>0,"No budget","—"),IF(D15>C15,"OVER",IF(D15/C15>=0.9,"Close","OK"))) -> OK
A16: Home Expenses | B16: Subscription | C16: =SUMIFS(Monthly!$D:$D,Monthly!$B:$B,$A16,Monthly!$C:$C,$B16) -> 210 | D16: =SUMIFS(Transactions!$E:$E,Transactions!$G:$G,$A16,Transactions!$H:$H,$B16,Transactions!$J:$J,$B$3,Transactions!$K:$K,$D$3) -> 0 | E16: =C16-D16 -> 210 | F16: =IFERROR(D16/C16,0) -> 0 | G16: =IF(C16=0,IF(D16>0,"No budget","—"),IF(D16>C16,"OVER",IF(D16/C16>=0.9,"Close","OK"))) -> OK
A17: Home Expenses | B17: Meal Plan | C17: =SUMIFS(Monthly!$D:$D,Monthly!$B:$B,$A17,Monthly!$C:$C,$B17) -> 1176 | D17: =SUMIFS(Transactions!$E:$E,Transactions!$G:$G,$A17,Transactions!$H:$H,$B17,Transactions!$J:$J,$B$3,Transactions!$K:$K,$D$3) -> 0 | E17: =C17-D17 -> 1176 | F17: =IFERROR(D17/C17,0) -> 0 | G17: =IF(C17=0,IF(D17>0,"No budget","—"),IF(D17>C17,"OVER",IF(D17/C17>=0.9,"Close","OK"))) -> OK
... A42: Investment | B42: Other Investment | C42: =SUMIFS(Monthly!$D:$D,Monthly!$B:$B,$A42,Monthly!$C:$C,$B42) -> 0 | D42: =SUMIFS(Transactions!$E:$E,Transactions!$G:$G,$A42,Transactions!$H:$H,$B42,Transactions!$J:$J,$B$3,Transactions!$K:$K,$D$3) -> 0 | E42: =C42-D42 -> 0 | F42: =IFERROR(D42/C42,0) -> 0 | G42: =IF(C42=0,IF(D42>0,"No budget","—"),IF(D42>C42,"OVER",IF(D42/C42>=0.9,"Close","OK"))) -> —
B43: Total | C43: =SUM(C6:C42) -> 18967.76 | D43: =SUM(D6:D42) -> 245.5 | E43: =C43-D43 -> 18722.26 | F43: =IFERROR(D43/C43,0) -> 0.012943015

Sheet Categories
A1: Category | B1: Segment | C1: Monthly budget | E1: The app reads this tab, so its buttons always match your sheet.
A2: Home Expenses | B2: Mortgage/Rent | C2: =SUMIFS(Monthly!$D:$D,Monthly!$B:$B,$A2,Monthly!$C:$C,$B2) -> 3465 | E2: Budgets are edited in Monthly (column D). This mirrors them.
A3: Home Expenses | B3: Phone Bills | C3: =SUMIFS(Monthly!$D:$D,Monthly!$B:$B,$A3,Monthly!$C:$C,$B3) -> 210
A4: Home Expenses | B4: Electricity and Water Bill | C4: =SUMIFS(Monthly!$D:$D,Monthly!$B:$B,$A4,Monthly!$C:$C,$B4) -> 500
A5: Home Expenses | B5: Gas Bill | C5: =SUMIFS(Monthly!$D:$D,Monthly!$B:$B,$A5,Monthly!$C:$C,$B5) -> 30
A6: Home Expenses | B6: Cable and Internet Bill | C6: =SUMIFS(Monthly!$D:$D,Monthly!$B:$B,$A6,Monthly!$C:$C,$B6) -> 326.76
A7: Home Expenses | B7: Cleaners | C7: =SUMIFS(Monthly!$D:$D,Monthly!$B:$B,$A7,Monthly!$C:$C,$B7) -> 145
A8: Home Expenses | B8: Home Supplies | C8: =SUMIFS(Monthly!$D:$D,Monthly!$B:$B,$A8,Monthly!$C:$C,$B8) -> 1000
A9: Home Expenses | B9: Water | C9: =SUMIFS(Monthly!$D:$D,Monthly!$B:$B,$A9,Monthly!$C:$C,$B9) -> 35
A10: Home Expenses | B10: Laundry | C10: =SUMIFS(Monthly!$D:$D,Monthly!$B:$B,$A10,Monthly!$C:$C,$B10) -> 50
A11: Home Expenses | B11: Food Delivery | C11: =SUMIFS(Monthly!$D:$D,Monthly!$B:$B,$A11,Monthly!$C:$C,$B11) -> 600
A12: Home Expenses | B12: Subscription | C12: =SUMIFS(Monthly!$D:$D,Monthly!$B:$B,$A12,Monthly!$C:$C,$B12) -> 210
A13: Home Expenses | B13: Meal Plan | C13: =SUMIFS(Monthly!$D:$D,Monthly!$B:$B,$A13,Monthly!$C:$C,$B13) -> 1176
A14: Home Expenses | B14: Other Home | C14: =SUMIFS(Monthly!$D:$D,Monthly!$B:$B,$A14,Monthly!$C:$C,$B14) -> 0
... A38: Investment | B38: Other Investment | C38: =SUMIFS(Monthly!$D:$D,Monthly!$B:$B,$A38,Monthly!$C:$C,$B38) -> 0
